Status 429: Too many requests
Ignore 429: Continue login
BTC price is 20211.77000000 USDT
Traceback (most recent call last):
  File "/usr/local/lib/python3.10/site-packages/instagrapi/mixins/private.py", line 298, in _send_private_request
    response.raise_for_status()
  File "/usr/local/lib/python3.10/site-packages/requests/models.py", line 1021, in raise_for_status
    raise HTTPError(http_error_msg, response=self)
requests.exceptions.HTTPError: 400 Client Error: Bad Request for url: https://i.instagram.com/api/v1/accounts/login/

During handling of the above exception, another exception occurred:

Traceback (most recent call last):
  File "/root/tgbot/main.py", line 28, in <module>
    import instaPy
  File "/root/tgbot/instaPy.py", line 4, in <module>
    cl.login("morrisjonson4","NfyR1945")
  File "/usr/local/lib/python3.10/site-packages/instagrapi/mixins/auth.py", line 391, in login
    logged = self.private_request("accounts/login/", data, login=True)
  File "/usr/local/lib/python3.10/site-packages/instagrapi/mixins/private.py", line 447, in private_request
    raise e
  File "/usr/local/lib/python3.10/site-packages/instagrapi/mixins/private.py", line 434, in private_request
    self._send_private_request(endpoint, **kwargs)
  File "/usr/local/lib/python3.10/site-packages/instagrapi/mixins/private.py", line 354, in _send_private_request
    raise UnknownError(**last_json)
instagrapi.exceptions.UnknownError: The username you entered doesn't appear to belong to an account. Please check your username and try again.
Status 429: Too many requests
Ignore 429: Continue login
BTC price is 20197.19000000 USDT
Traceback (most recent call last):
  File "/usr/local/lib/python3.10/site-packages/instagrapi/mixins/private.py", line 298, in _send_private_request
    response.raise_for_status()
  File "/usr/local/lib/python3.10/site-packages/requests/models.py", line 1021, in raise_for_status
    raise HTTPError(http_error_msg, response=self)
requests.exceptions.HTTPError: 400 Client Error: Bad Request for url: https://i.instagram.com/api/v1/accounts/login/

During handling of the above exception, another exception occurred:

Traceback (most recent call last):
  File "/root/tgbot/main.py", line 28, in <module>
    import instaPy
  File "/root/tgbot/instaPy.py", line 4, in <module>
    cl.login("morrisjonson4","NfyR1945")
  File "/usr/local/lib/python3.10/site-packages/instagrapi/mixins/auth.py", line 391, in login
    logged = self.private_request("accounts/login/", data, login=True)
  File "/usr/local/lib/python3.10/site-packages/instagrapi/mixins/private.py", line 447, in private_request
    raise e
  File "/usr/local/lib/python3.10/site-packages/instagrapi/mixins/private.py", line 434, in private_request
    self._send_private_request(endpoint, **kwargs)
  File "/usr/local/lib/python3.10/site-packages/instagrapi/mixins/private.py", line 354, in _send_private_request
    raise UnknownError(**last_json)
instagrapi.exceptions.UnknownError: The username you entered doesn't appear to belong to an account. Please check your username and try again.
BTC price is 20196.46000000 USDT
bot is active
2022-08-29 14:48:13,755 (__init__.py:884 MainThread) ERROR - TeleBot: "Infinity polling: polling exited"
2022-08-29 14:48:13,756 (__init__.py:886 MainThread) ERROR - TeleBot: "Break infinity polling"
BTC price is 20203.82000000 USDT
bot is active
2022-08-29 14:48:50,423 (__init__.py:884 MainThread) ERROR - TeleBot: "Infinity polling: polling exited"
2022-08-29 14:48:50,423 (__init__.py:886 MainThread) ERROR - TeleBot: "Break infinity polling"
BTC price is 20210.00000000 USDT
bot is active
https://www.tiktok.com/@methnmilkshake/video/7059106398214409477?is_copy_url=1&is_from_webapp=v1
2022-08-30 11:37:46,460 (__init__.py:878 MainThread) ERROR - TeleBot: "Infinity polling exception: [Errno 2] No such file or directory: 'you-get'"
2022-08-30 11:37:46,471 (__init__.py:880 MainThread) ERROR - TeleBot: "Exception traceback:
Traceback (most recent call last):
  File "/usr/local/lib/python3.10/site-packages/telebot/__init__.py", line 874, in infinity_polling
    self.polling(non_stop=True, timeout=timeout, long_polling_timeout=long_polling_timeout,
  File "/usr/local/lib/python3.10/site-packages/telebot/__init__.py", line 946, in polling
    self.__threaded_polling(non_stop=non_stop, interval=interval, timeout=timeout, long_polling_timeout=long_polling_timeout,
  File "/usr/local/lib/python3.10/site-packages/telebot/__init__.py", line 1021, in __threaded_polling
    raise e
  File "/usr/local/lib/python3.10/site-packages/telebot/__init__.py", line 977, in __threaded_polling
    self.worker_pool.raise_exceptions()
  File "/usr/local/lib/python3.10/site-packages/telebot/util.py", line 154, in raise_exceptions
    raise self.exception_info
  File "/usr/local/lib/python3.10/site-packages/telebot/util.py", line 98, in run
    task(*args, **kwargs)
  File "/root/tgbot/main.py", line 313, in you_get_2
    subprocess.call(['you-get',message.text,'-O','file'])
  File "/usr/local/lib/python3.10/subprocess.py", line 345, in call
    with Popen(*popenargs, **kwargs) as p:
  File "/usr/local/lib/python3.10/subprocess.py", line 969, in __init__
    self._execute_child(args, executable, preexec_fn, close_fds,
  File "/usr/local/lib/python3.10/subprocess.py", line 1845, in _execute_child
    raise child_exception_type(errno_num, err_msg, err_filename)
FileNotFoundError: [Errno 2] No such file or directory: 'you-get'
"
https://www.tiktok.com/@bloodwigg/video/6924083259873692933?is_copy_url=1&is_from_webapp=v1
2022-09-10 14:41:44,106 (__init__.py:878 MainThread) ERROR - TeleBot: "Infinity polling exception: [Errno 2] No such file or directory: 'you-get'"
2022-09-10 14:41:44,109 (__init__.py:880 MainThread) ERROR - TeleBot: "Exception traceback:
Traceback (most recent call last):
  File "/usr/local/lib/python3.10/site-packages/telebot/__init__.py", line 874, in infinity_polling
    self.polling(non_stop=True, timeout=timeout, long_polling_timeout=long_polling_timeout,
  File "/usr/local/lib/python3.10/site-packages/telebot/__init__.py", line 946, in polling
    self.__threaded_polling(non_stop=non_stop, interval=interval, timeout=timeout, long_polling_timeout=long_polling_timeout,
  File "/usr/local/lib/python3.10/site-packages/telebot/__init__.py", line 1021, in __threaded_polling
    raise e
  File "/usr/local/lib/python3.10/site-packages/telebot/__init__.py", line 977, in __threaded_polling
    self.worker_pool.raise_exceptions()
  File "/usr/local/lib/python3.10/site-packages/telebot/util.py", line 154, in raise_exceptions
    raise self.exception_info
  File "/usr/local/lib/python3.10/site-packages/telebot/util.py", line 98, in run
    task(*args, **kwargs)
  File "/root/tgbot/main.py", line 313, in you_get_2
    subprocess.call(['you-get',message.text,'-O','file'])
  File "/usr/local/lib/python3.10/subprocess.py", line 345, in call
    with Popen(*popenargs, **kwargs) as p:
  File "/usr/local/lib/python3.10/subprocess.py", line 969, in __init__
    self._execute_child(args, executable, preexec_fn, close_fds,
  File "/usr/local/lib/python3.10/subprocess.py", line 1845, in _execute_child
    raise child_exception_type(errno_num, err_msg, err_filename)
FileNotFoundError: [Errno 2] No such file or directory: 'you-get'
"
https://www.tiktok.com/@bloodwigg/video/6924083259873692933?is_copy_url=1&is_from_webapp=v1
Site:       TikTok.com
Title:      Clyde [6924083259873692933]
Type:       MPEG-4 video (video/mp4)
Size:       2.92 MiB (3061475 Bytes)

Downloading file.mp4 ...
 0.0% (  0.0/  2.9MB) ├────────────────────────────────────────┤[1/1]  8.6% (  0.2/  2.9MB) ├████────────────────────────────────────┤[1/1]    4 MB/s17.1% (  0.5/  2.9MB) ├███████─────────────────────────────────┤[1/1]   94 MB/s25.7% (  0.8/  2.9MB) ├███████████─────────────────────────────┤[1/1]   33 MB/s34.3% (  1.0/  2.9MB) ├██████████████──────────────────────────┤[1/1]   68 MB/s42.8% (  1.2/  2.9MB) ├█████████████████───────────────────────┤[1/1]   66 MB/s51.4% (  1.5/  2.9MB) ├█████████████████████───────────────────┤[1/1]   91 MB/s59.9% (  1.8/  2.9MB) ├████████████████████████────────────────┤[1/1]   66 MB/s68.5% (  2.0/  2.9MB) ├████████████████████████████────────────┤[1/1]   65 MB/s77.1% (  2.2/  2.9MB) ├███████████████████████████████─────────┤[1/1]   63 MB/s85.6% (  2.5/  2.9MB) ├███████████████████████████████████─────┤[1/1]   94 MB/s94.2% (  2.8/  2.9MB) ├██████████████████████████████████████──┤[1/1]   71 MB/s 100% (  2.9/  2.9MB) ├████████████████████████████████████████┤[1/1]   62 MB/s

https://www.tiktok.com/@bloodwigg/video/6924083259873692933?is_copy_url=1&is_from_webapp=v1
2022-09-10 14:50:06,347 (__init__.py:878 MainThread) ERROR - TeleBot: "Infinity polling exception: [Errno 2] No such file or directory: 'you-get'"
2022-09-10 14:50:06,348 (__init__.py:880 MainThread) ERROR - TeleBot: "Exception traceback:
Traceback (most recent call last):
  File "/usr/local/lib/python3.10/site-packages/telebot/__init__.py", line 874, in infinity_polling
    self.polling(non_stop=True, timeout=timeout, long_polling_timeout=long_polling_timeout,
  File "/usr/local/lib/python3.10/site-packages/telebot/__init__.py", line 946, in polling
    self.__threaded_polling(non_stop=non_stop, interval=interval, timeout=timeout, long_polling_timeout=long_polling_timeout,
  File "/usr/local/lib/python3.10/site-packages/telebot/__init__.py", line 1021, in __threaded_polling
    raise e
  File "/usr/local/lib/python3.10/site-packages/telebot/__init__.py", line 977, in __threaded_polling
    self.worker_pool.raise_exceptions()
  File "/usr/local/lib/python3.10/site-packages/telebot/util.py", line 154, in raise_exceptions
    raise self.exception_info
  File "/usr/local/lib/python3.10/site-packages/telebot/util.py", line 98, in run
    task(*args, **kwargs)
  File "/root/tgbot/main.py", line 313, in you_get_2
    tyr:
  File "/usr/local/lib/python3.10/subprocess.py", line 345, in call
    with Popen(*popenargs, **kwargs) as p:
  File "/usr/local/lib/python3.10/subprocess.py", line 969, in __init__
    self._execute_child(args, executable, preexec_fn, close_fds,
  File "/usr/local/lib/python3.10/subprocess.py", line 1845, in _execute_child
    raise child_exception_type(errno_num, err_msg, err_filename)
FileNotFoundError: [Errno 2] No such file or directory: 'you-get'
"
BTC price is 21474.87000000 USDT
bot is active
https://www.instagram.com/p/Ce8YFeNj4Pp/
Status 429: Too many requests
Ignore 429: Continue login
BTC price is 19208.75000000 USDT
bot is active
BTC price is 19201.28000000 USDT
bot is active
BTC price is 19528.32000000 USDT
bot is active
BTC price is 19535.91000000 USDT
bot is active
BTC price is 19559.45000000 USDT
bot is active
